Workbook

Sheet Synthèse
A1: Macro-chiffrage — Migration Cloudera → Cloud privé DMZR (K8s / Airflow)
A2: Équipe Stress Test — Chaîne IHM / IFRS9 / CRR3 / Projection / TS EAD FWD
A4: Indicateurs clés | D4: Répartition par lot
A5: Charge totale retenue (JH) | B5: =Chiffrage_Détaillé!F62 -> 659 | D5: Lot | E5: JH | F5: Coût (€)
A6: Fourchette basse (JH) | B6: =Chiffrage_Détaillé!D62 -> 475 | D6: LOT 1 — Cadrage & Architecture | E6: =Chiffrage_Détaillé!F9 -> 61 | F6: =Chiffrage_Détaillé!H9 -> 39650
A7: Fourchette haute (JH) | B7: =Chiffrage_Détaillé!E62 -> 843 | D7: LOT 2 — Infrastructure & Plateforme | E7: =Chiffrage_Détaillé!F17 -> 88 | F7: =Chiffrage_Détaillé!H17 -> 57200
A8: TJM moyen pondéré | B8: =Hypothèses!$B$4 -> 650 | D8: LOT 3 — Migration applicative Spark | E8: =Chiffrage_Détaillé!F24 -> 85 | F8: =Chiffrage_Détaillé!H24 -> 55250
A9: Coût hors aléas | B9: =Chiffrage_Détaillé!H62 -> 428350 | D9: LOT 4 — Orchestration (Oozie → Airflow) | E9: =Chiffrage_Détaillé!F30 -> 76 | F9: =Chiffrage_Détaillé!H30 -> 49400
A10: Provision aléas | B10: =Chiffrage_Détaillé!H63 -> 64252.5 | D10: LOT 5 — Application IHM (Back / Front) | E10: =Chiffrage_Détaillé!F37 -> 79 | F10: =Chiffrage_Détaillé!H37 -> 51350
A11: COÛT TOTAL ESTIMÉ | B11: =Chiffrage_Détaillé!H64 -> 492602.5 | D11: LOT 6 — Migration des données | E11: =Chiffrage_Détaillé!F42 -> 41 | F11: =Chiffrage_Détaillé!H42 -> 26650
D12: LOT 7 — Recette & Validation | E12: =Chiffrage_Détaillé!F49 -> 110 | F12: =Chiffrage_Détaillé!H49 -> 71500
A13: Fourchette de coût (aléas inclus) | D13: LOT 8 — Bascule & Run | E13: =Chiffrage_Détaillé!F55 -> 47 | F13: =Chiffrage_Détaillé!H55 -> 30550
A14: Estimation basse | B14: =Chiffrage_Détaillé!D62*Hypothèses!$B$4*(1+Hypothèses!$B$5) -> 355062.5 | D14: LOT 9 — Pilotage & Transverse | E14: =Chiffrage_Détaillé!F60 -> 72 | F14: =Chiffrage_Détaillé!H60 -> 46800
A15: Estimation haute | B15: =Chiffrage_Détaillé!E62*Hypothèses!$B$4*(1+Hypothèses!$B$5) -> 630142.5 | D15: TOTAL | E15: =SUM(E6:E14) -> 659 | F15: =SUM(F6:F14) -> 428350

Sheet Hypothèses
A1: Hypothèses de chiffrage
A3: Paramètre | B3: Valeur | C3: Commentaire
A4: TJM moyen pondéré (€/JH) | B4: 650 | C4: Taux journalier moyen mixte (architecte / dev / QA / PMO) — à ajuster
A5: Provision aléas & risques (%) | B5: 0.15 | C5: Marge d'incertitude appliquée sur le coût hors aléas (macro-chiffrage)
A6: Nombre de chaînes de traitement métier | B6: 5 | C6: IFRS9, CRR3, Projection, TS EAD FWD, + autres (informatif)
A7: Devise | B7: EUR
A9: Périmètre & exclusions
A10: • Chiffrage macro (Rough Order of Magnitude) : fourchette basse/haute + valeur retenue par tâche.
A11: • Inclus : cadrage, plateforme K8s, migration Spark, réécriture orchestration (Oozie→Airflow), refonte IHM, migration données, recette (dont non-régression réglementaire), bascule, run initial.
A12: • Exclus : coûts d'infrastructure/licences (compute, stockage objet, réseau DMZR), coûts matériels, coûts de maintenance récurrente au-delà de l'hypercare.
A13: • Le PMO est chiffré en tant que lot (LOT 9) et non en pourcentage, pour éviter les doubles comptes.
A14: • Les JH 'retenu' sont des estimations expertes situées dans la fourchette min/max (cellules bleues = saisie modifiable).

Sheet Cartographie_Impacts
A1: Cartographie des impacts — Cloudera → Cloud privé DMZR (Kubernetes / Airflow)
A3: Composant / Brique | B3: Techno source (Cloudera) | C3: Techno cible (Cloud privé DMZR) | D3: Nature de l'impact | E3: Complexité | F3: Lot
A4: Moteur de calcul | B4: Spark on YARN | C4: Spark on Kubernetes (Spark Operator / SparkApplication CRD) | D4: JARs quasi inchangés ; conteneurisation, images, service de shuffle, retuning mémoire. | E4: Moyenne | F4: LOT 3
A5: Orchestration | B5: Oozie (workflows XML, coordinators) | C5: Airflow (DAGs Python) | D5: Réécriture complète : chaque spark-action → opérateur K8s ; coordinators → schedules. | E5: Forte | F5: LOT 4
A6: Stockage données | B6: HDFS | C6: Stockage objet S3-compatible (MinIO / Ceph RGW) | D6: Chemins hdfs:// → s3a:// ; impacte jobs, locations Hive et parcours fichiers IHM. | E6: Forte | F6: LOT 3/6
A7: Métastore | B7: Hive Metastore (CDP) | C7: Hive Metastore autonome sur K8s + BDD (PostgreSQL) | D7: Redéploiement HMS ; repointage des locations des tables externes ORC. | E7: Moyenne | F7: LOT 2/6
A8: Ordonnancement ressources | B8: Files de capacité YARN (Capacity Scheduler) | C8: Scheduler batch Yunikorn (files hiérarchiques) | D8: K8s n'a pas de notion de file ; Yunikorn restitue la sémantique de capacité YARN. | E8: Forte | F8: LOT 2/5
A9: Contrôle capacité file (IHM) | B9: YARN ResourceManager REST API | C9: API Yunikorn / API K8s | D9: Le back IHM interroge Yunikorn au lieu de YARN avant lancement. | E9: Moyenne | F9: LOT 5
A10: IHM — Back (lancement jobs) | B10: Client Oozie REST | C10: Client Airflow REST API (trigger DAG) | D10: Refonte de la couche d'intégration d'orchestration. | E10: Forte | F10: LOT 5
A11: IHM — Back (fichiers) | B11: WebHDFS (upload / parcours) | C11: SDK S3 (upload / parcours bucket) | D11: Refonte upload et navigation fichiers ; sélection fichiers stockés → bucket. | E11: Forte | F11: LOT 5
A12: IHM — Front | B12: Écrans lancement & sélection fichiers | C12: Idem (adaptation parcours/objets) | D12: Logique majoritairement conservée ; adaptations d'intégration. | E12: Moyenne | F12: LOT 5
A13: Sécurité | B13: Kerberos (bout-en-bout) | C13: Service Accounts + Secrets K8s (Kerberos résiduel HMS/store) | D13: Modèle d'authentification revu ; point sensible en zone DMZR. | E13: Forte | F13: LOT 1/5
A14: CI/CD & packaging | B14: Build JAR + dépôt HDFS | C14: Build images conteneurs + registry + déploiement K8s | D14: Nouvelle chaîne de build/livraison des applications. | E14: Moyenne | F14: LOT 2
A15: Applications métier | B15: IFRS9, CRR3, Projection, TS EAD FWD, +autres | C15: Idem (adaptées K8s/S3A) | D15: Adaptation + validation iso-résultats par chaîne (enjeu réglementaire). | E15: Forte | F15: LOT 3/7

Sheet Chiffrage_Détaillé
A1: Chiffrage détaillé (macro / ROM)
A3: Lot / Tâche | B3: Composant (source → cible) | C3: Complexité | D3: JH min | E3: JH max | F3: JH retenu | G3: TJM (€) | H3: Coût (€)
A4: LOT 1 — Cadrage & Architecture
A5: Étude d'architecture cible (K8s, réseau DMZR, stockage objet) | B5: Cluster / réseau / stockage | C5: Forte | D5: 15 | E5: 25 | F5: 20 | G5: =Hypothèses!$B$4 -> 650 | H5: =F5*G5 -> 13000
A6: Design détaillé orchestration Airflow (framework DAG, conventions) | B6: Oozie → Airflow | C6: Moyenne | D6: 10 | E6: 18 | F6: 14 | G6: =Hypothèses!$B$4 -> 650 | H6: =F6*G6 -> 9100
A7: Design sécurité (Service Accounts, Secrets, Kerberos HMS/store) | B7: Kerberos → SA/Secrets | C7: Forte | D7: 10 | E7: 20 | F7: 15 | G7: =Hypothèses!$B$4 -> 650 | H7: =F7*G7 -> 9750
A8: Design stockage objet & stratégie de migration des données | B8: HDFS → S3 | C8: Moyenne | D8: 8 | E8: 15 | F8: 12 | G8: =Hypothèses!$B$4 -> 650 | H8: =F8*G8 -> 7800
A9: Sous-total LOT 1 | D9: =SUM(D5:D8) -> 43 | E9: =SUM(E5:E8) -> 78 | F9: =SUM(F5:F8) -> 61 | H9: =SUM(H5:H8) -> 39650
A10: LOT 2 — Infrastructure & Plateforme
A11: Provisioning cluster K8s, namespaces, ResourceQuota | B11: — | C11: Forte | D11: 15 | E11: 25 | F11: 20 | G11: =Hypothèses!$B$4 -> 650 | H11: =F11*G11 -> 13000
A12: Déploiement Spark Operator + construction des images Spark | B12: Spark on K8s | C12: Moyenne | D12: 10 | E12: 18 | F12: 14 | G12: =Hypothèses!$B$4 -> 650 | H12: =F12*G12 -> 9100
A13: Déploiement Yunikorn (scheduler batch + files hiérarchiques) | B13: Capacity Sched. → Yunikorn | C13: Forte | D13: 10 | E13: 18 | F13: 14 | G13: =Hypothèses!$B$4 -> 650 | H13: =F13*G13 -> 9100
A14: Déploiement Hive Metastore autonome + base (PostgreSQL) | B14: HMS CDP → HMS K8s | C14: Moyenne | D14: 10 | E14: 15 | F14: 12 | G14: =Hypothèses!$B$4 -> 650 | H14: =F14*G14 -> 7800
A15: Mise en place stockage objet S3 (MinIO/Ceph) + buckets/policies | B15: HDFS → S3 | C15: Moyenne | D15: 10 | E15: 18 | F15: 14 | G15: =Hypothèses!$B$4 -> 650 | H15: =F15*G15 -> 9100
A16: Chaîne CI/CD (build images, registry, déploiement) | B16: Build JAR → images | C16: Moyenne | D16: 10 | E16: 18 | F16: 14 | G16: =Hypothèses!$B$4 -> 650 | H16: =F16*G16 -> 9100
A17: Sous-total LOT 2 | D17: =SUM(D11:D16) -> 65 | E17: =SUM(E11:E16) -> 112 | F17: =SUM(F11:F16) -> 88 | H17: =SUM(H11:H16) -> 57200
A18: LOT 3 — Migration applicative Spark
A19: Adaptation soumission Spark YARN → K8s (SparkApplication CRD) | B19: Spark on YARN → K8s | C19: Moyenne | D19: 8 | E19: 14 | F19: 11 | G19: =Hypothèses!$B$4 -> 650 | H19: =F19*G19 -> 7150
A20: Adaptation des chemins HDFS → S3A dans les jobs | B20: HDFS → S3A | C20: Moyenne | D20: 10 | E20: 16 | F20: 13 | G20: =Hypothèses!$B$4 -> 650 | H20: =F20*G20 -> 8450
A21: Tuning mémoire/shuffle K8s (dont résolution OOM EXPORT_MATRICES) | B21: YARN overhead → pod limits | C21: Forte | D21: 10 | E21: 18 | F21: 14 | G21: =Hypothèses!$B$4 -> 650 | H21: =F21*G21 -> 9100
A22: Adaptation tables Hive externes (repointage des locations) | B22: Locations ORC | C22: Faible | D22: 5 | E22: 10 | F22: 7 | G22: =Hypothèses!$B$4 -> 650 | H22: =F22*G22 -> 4550
A23: Adaptation & validation par application (IFRS9, CRR3, Projection, TS EAD FWD, +autres) | B23: Applications métier | C23: Forte | D23: 30 | E23: 50 | F23: 40 | G23: =Hypothèses!$B$4 -> 650 | H23: =F23*G23 -> 26000
A24: Sous-total LOT 3 | D24: =SUM(D19:D23) -> 63 | E24: =SUM(E19:E23) -> 108 | F24: =SUM(F19:F23) -> 85 | H24: =SUM(H19:H23) -> 55250
A25: LOT 4 — Orchestration (Oozie → Airflow)
A26: Framework & templates DAG, opérateurs standard (SparkKubernetesOperator) | B26: Oozie → Airflow | C26: Moyenne | D26: 10 | E26: 18 | F26: 14 | G26: =Hypothèses!$B$4 -> 650 | H26: =F26*G26 -> 9100
A27: Réécriture des workflows par chaîne de traitement | B27: Workflows XML → DAGs | C27: Forte | D27: 30 | E27: 50 | F27: 40 | G27: =Hypothèses!$B$4 -> 650 | H27: =F27*G27 -> 26000
A28: Migration coordinators → schedules / triggers | B28: Coordinators → schedule | C28: Moyenne | D28: 8 | E28: 14 | F28: 11 | G28: =Hypothèses!$B$4 -> 650 | H28: =F28*G28 -> 7150
A29: Gestion des dépendances & reprise sur erreur | B29: — | C29: Moyenne | D29: 8 | E29: 15 | F29: 11 | G29: =Hypothèses!$B$4 -> 650 | H29: =F29*G29 -> 7150
A30: Sous-total LOT 4 | D30: =SUM(D26:D29) -> 56 | E30: =SUM(E26:E29) -> 97 | F30: =SUM(F26:F29) -> 76 | H30: =SUM(H26:H29) -> 49400
A31: LOT 5 — Application IHM (Back / Front)
A32: Refonte client orchestration (Oozie REST → Airflow REST API) | B32: Oozie REST → Airflow API | C32: Forte | D32: 15 | E32: 25 | F32: 20 | G32: =Hypothèses!$B$4 -> 650 | H32: =F32*G32 -> 13000
A33: Refonte accès fichiers (WebHDFS → SDK S3 : upload / parcours) | B33: WebHDFS → SDK S3 | C33: Forte | D33: 15 | E33: 25 | F33: 20 | G33: =Hypothèses!$B$4 -> 650 | H33: =F33*G33 -> 13000
A34: Refonte contrôle capacité file (YARN RM API → Yunikorn API) | B34: YARN RM → Yunikorn | C34: Moyenne | D34: 8 | E34: 15 | F34: 12 | G34: =Hypothèses!$B$4 -> 650 | H34: =F34*G34 -> 7800
A35: Adaptation Front (parcours fichiers, écrans de lancement) | B35: Front | C35: Moyenne | D35: 10 | E35: 20 | F35: 15 | G35: =Hypothèses!$B$4 -> 650 | H35: =F35*G35 -> 9750
A36: Authentification & sécurisation IHM en zone DMZR | B36: Sécurité | C36: Moyenne | D36: 8 | E36: 15 | F36: 12 | G36: =Hypothèses!$B$4 -> 650 | H36: =F36*G36 -> 7800
A37: Sous-total LOT 5 | D37: =SUM(D32:D36) -> 56 | E37: =SUM(E32:E36) -> 100 | F37: =SUM(F32:F36) -> 79 | H37: =SUM(H32:H36) -> 51350
A38: LOT 6 — Migration des données
A39: Transfert des données HDFS → stockage objet | B39: HDFS → S3 | C39: Moyenne | D39: 10 | E39: 20 | F39: 15 | G39: =Hypothèses!$B$4 -> 650 | H39: =F39*G39 -> 9750
A40: Migration du métastore Hive + repointage des locations | B40: HMS | C40: Moyenne | D40: 8 | E40: 15 | F40: 12 | G40: =Hypothèses!$B$4 -> 650 | H40: =F40*G40 -> 7800
A41: Réconciliation & contrôle d'intégrité des données | B41: Contrôle | C41: Forte | D41: 10 | E41: 18 | F41: 14 | G41: =Hypothèses!$B$4 -> 650 | H41: =F41*G41 -> 9100
...

Sheet Risques
A1: Principaux risques & points de vigilance
A3: Risque | B3: Description | C3: Impact | D3: Probabilité | E3: Mitigation
A4: Non-régression réglementaire | B4: Résultats stress test non iso après migration (S3A/K8s, ordres de calcul). | C4: Élevé | D4: Moyenne | E4: Campagne de non-régression exhaustive, jeux de données figés, comparaison bit-à-bit.
A5: Sécurité en zone DMZR | B5: Modèle Kerberos → SA/Secrets ; contraintes réseau/flux DMZR. | C5: Élevé | D5: Élevée | E5: Design sécurité amont, validation RSSI, PoC d'authentification HMS/stockage.
A6: Perte de data-locality (S3) | B6: Dégradation de performance vs HDFS sur certains traitements. | C6: Moyen | D6: Moyenne | E6: Tests de perf, tuning I/O, cache, dimensionnement compute.
A7: Sémantique des files de capacité | B7: Comportement Yunikorn ≠ Capacity Scheduler YARN. | C7: Moyen | D7: Moyenne | E7: PoC Yunikorn, calibrage des files, adaptation du contrôle IHM.
A8: Réécriture Oozie → Airflow | B8: Volume et complexité des workflows sous-estimés. | C8: Élevé | D8: Moyenne | E8: Templates DAG réutilisables, réécriture par lot, revue croisée.
A9: OOM driver sur K8s | B9: Pods OOM-killed (EXPORT_MATRICES) sans buffer overhead YARN. | C9: Moyen | D9: Moyenne | E9: memoryOverheadFactor, checkpoints, écritures intermédiaires, maxPlanStringLength.
A10: Dépendance équipes infra/RSSI | B10: Provisioning K8s, stockage objet, flux DMZR hors périmètre équipe. | C10: Moyen | D10: Élevée | E10: Cadrage RACI amont, jalons de dépendance, plan de commande infra.
